Workbook

Sheet Assumptions
A1: MCA BROKERAGE FINANCIAL MODEL — MFunding.com
A2: Key Assumptions & Inputs (Blue values = adjustable inputs)
A4: LEAD ACQUISITION COSTS
B5: Category | C5: Conservative | D5: Most Likely | E5: Optimistic | F5: Notes
A6: 1 | B6: Live Transfer Cost (per lead) | C6: 100 | D6: 75 | E6: 50 | F6: Primary channel — price varies by provider
A7: 2 | B7: Google Ads Cost Per Lead | C7: 80 | D7: 60 | E7: 40 | F7: Geo-targeted per city campaigns
A8: 3 | B8: Live Transfers / Month | C8: 60 | D8: 100 | E8: 150 | F8: Scale up as pipeline proves out
A9: 4 | B9: Google Ads Leads / Month | C9: 20 | D9: 40 | E9: 80 | F9: Starting $50-100/day across cities
A10: 5 | B10: Total Leads / Month | C10: =C8+C9 | D10: =D8+D9 | E10: =E8+E9 | F10: Sum of all lead sources
A12: CONVERSION FUNNEL
B13: Category | C13: Conservative | D13: Most Likely | E13: Optimistic | F13: Notes
A14: 6 | B14: Contact Rate (% of leads reached) | C14: 0.5 | D14: 0.65 | E14: 0.8 | F14: Live transfers have higher contact rates
A15: 7 | B15: Application Rate (% of contacted) | C15: 0.25 | D15: 0.35 | E15: 0.45 | F15: % who submit full app + bank statements
A16: 8 | B16: Approval Rate (% of applications) | C16: 0.55 | D16: 0.65 | E16: 0.75 | F16: Depends on lead quality + funder relationships
A17: 9 | B17: Funding Rate (% of approved) | C17: 0.7 | D17: 0.8 | E17: 0.9 | F17: % of approved deals that actually fund
A19: DEAL ECONOMICS
B20: Category | C20: Conservative | D20: Most Likely | E20: Optimistic | F20: Notes
A21: 10 | B21: Average Deal Size (funded amount) | C21: 35000 | D21: 50000 | E21: 75000 | F21: Typical MCA range $10K-$250K
A22: 11 | B22: Commission Points (% of funded) | C22: 0.06 | D22: 0.08 | E22: 0.1 | F22: Broker commission: 5-12 points typical
A23: 12 | B23: Renewal Rate (% come back in 6 mo) | C23: 0.3 | D23: 0.45 | E23: 0.6 | F23: ~60% of MCA clients seek more capital
A24: 13 | B24: Renewal Commission Points | C24: 0.04 | D24: 0.06 | E24: 0.08 | F24: Usually slightly lower on renewals
A26: MONTHLY FIXED COSTS
B27: Expense Item | C27: Monthly Cost | F27: Notes
A28: A | B28: GoHighLevel (SaaS Pro) | C28: 497 | F28: CRM, landing pages, automation, AI Employee
A29: B | B29: Plaid Integration (or LendSaaS) | C29: 200 | F29: Bank verification API — volume pricing
A30: C | B30: Phone System / Dialer | C30: 150 | F30: For taking live transfers + outbound
A31: D | B31: Website Hosting (mfunding.com) | C31: 50 | F31: React app hosting (Vercel/Netlify)
A32: E | B32: Business Insurance / Compliance | C32: 200 | F32: E&O insurance, state registrations
A33: F | B33: Miscellaneous / Software | C33: 150 | F33: CRM add-ons, email tools, etc.
B34: TOTAL MONTHLY FIXED COSTS | C34: =SUM(C28:C33)

Sheet Monthly P&L
A1: 12-MONTH PROFIT & LOSS PROJECTION — MOST LIKELY SCENARIO
A2: Based on 'Most Likely' assumptions from Assumptions tab — ramp-up modeled with growth multipliers
C4: Month 1 | D4: Month 2 | E4: Month 3 | F4: Month 4 | G4: Month 5 | H4: Month 6 | I4: Month 7 | J4: Month 8 | K4: Month 9 | L4: Month 10 | M4: Month 11 | N4: Month 12 | O4: ANNUAL
B5: Ramp-Up Multiplier | C5: 0.25 | D5: 0.4 | E5: 0.6 | F5: 0.75 | G5: 0.85 | H5: 1 | I5: 1 | J5: 1.1 | K5: 1.15 | L5: 1.2 | M5: 1.25 | N5: 1.3
A7: LEAD VOLUME
B8: Live Transfers | C8: =Assumptions!D8*C5 | D8: =Assumptions!D8*D5 | E8: =Assumptions!D8*E5 | F8: =Assumptions!D8*F5 | G8: =Assumptions!D8*G5 | H8: =Assumptions!D8*H5 | I8: =Assumptions!D8*I5 | J8: =Assumptions!D8*J5 | K8: =Assumptions!D8*K5 | L8: =Assumptions!D8*L5 | M8: =Assumptions!D8*M5 | N8: =Assumptions!D8*N5 | O8: =SUM(C8:N8)
B9: Google Ads Leads | C9: =Assumptions!D9*C5 | D9: =Assumptions!D9*D5 | E9: =Assumptions!D9*E5 | F9: =Assumptions!D9*F5 | G9: =Assumptions!D9*G5 | H9: =Assumptions!D9*H5 | I9: =Assumptions!D9*I5 | J9: =Assumptions!D9*J5 | K9: =Assumptions!D9*K5 | L9: =Assumptions!D9*L5 | M9: =Assumptions!D9*M5 | N9: =Assumptions!D9*N5 | O9: =SUM(C9:N9)
B10: Total Leads | C10: =C8+C9 | D10: =D8+D9 | E10: =E8+E9 | F10: =F8+F9 | G10: =G8+G9 | H10: =H8+H9 | I10: =I8+I9 | J10: =J8+J9 | ... O10: =O8+O9
A12: CONVERSION FUNNEL
B13: Leads Contacted | C13: =C10*Assumptions!D14 | D13: =D10*Assumptions!D14 | E13: =E10*Assumptions!D14 | F13: =F10*Assumptions!D14 | G13: =G10*Assumptions!D14 | H13: =H10*Assumptions!D14 | I13: =I10*Assumptions!D14 | J13: =J10*Assumptions!D14 | K13: =K10*Assumptions!D14 | L13: =L10*Assumptions!D14 | M13: =M10*Assumptions!D14 | N13: =N10*Assumptions!D14 | O13: =SUM(C13:N13)
B14: Applications Submitted | C14: =C13*Assumptions!D15 | D14: =D13*Assumptions!D15 | E14: =E13*Assumptions!D15 | F14: =F13*Assumptions!D15 | G14: =G13*Assumptions!D15 | H14: =H13*Assumptions!D15 | I14: =I13*Assumptions!D15 | J14: =J13*Assumptions!D15 | K14: =K13*Assumptions!D15 | L14: =L13*Assumptions!D15 | M14: =M13*Assumptions!D15 | N14: =N13*Assumptions!D15 | O14: =SUM(C14:N14)
B15: Deals Approved | C15: =C14*Assumptions!D16 | D15: =D14*Assumptions!D16 | E15: =E14*Assumptions!D16 | F15: =F14*Assumptions!D16 | G15: =G14*Assumptions!D16 | H15: =H14*Assumptions!D16 | I15: =I14*Assumptions!D16 | J15: =J14*Assumptions!D16 | K15: =K14*Assumptions!D16 | L15: =L14*Assumptions!D16 | M15: =M14*Assumptions!D16 | N15: =N14*Assumptions!D16 | O15: =SUM(C15:N15)
B16: Deals Funded (New) | C16: =C15*Assumptions!D17 | D16: =D15*Assumptions!D17 | E16: =E15*Assumptions!D17 | F16: =F15*Assumptions!D17 | G16: =G15*Assumptions!D17 | H16: =H15*Assumptions!D17 | I16: =I15*Assumptions!D17 | J16: =J15*Assumptions!D17 | K16: =K15*Assumptions!D17 | L16: =L15*Assumptions!D17 | M16: =M15*Assumptions!D17 | N16: =N15*Assumptions!D17 | O16: =SUM(C16:N16)
B17: Renewal Deals | C17: 0 | D17: 0 | E17: 0 | F17: 0 | G17: 0 | H17: 0 | I17: =C16*Assumptions!D23 | J17: =D16*Assumptions!D23 | K17: =E16*Assumptions!D23 | L17: =F16*Assumptions!D23 | M17: =G16*Assumptions!D23 | N17: =H16*Assumptions!D23 | O17: =SUM(C17:N17)
A19: REVENUE
B20: New Deal Commission | C20: =C16*Assumptions!D21*Assumptions!D22 | D20: =D16*Assumptions!D21*Assumptions!D22 | E20: =E16*Assumptions!D21*Assumptions!D22 | F20: =F16*Assumptions!D21*Assumptions!D22 | G20: =G16*Assumptions!D21*Assumptions!D22 | H20: =H16*Assumptions!D21*Assumptions!D22 | I20: =I16*Assumptions!D21*Assumptions!D22 | J20: =J16*Assumptions!D21*Assumptions!D22 | K20: =K16*Assumptions!D21*Assumptions!D22 | L20: =L16*Assumptions!D21*Assumptions!D22 | M20: =M16*Assumptions!D21*Assumptions!D22 | N20: =N16*Assumptions!D21*Assumptions!D22 | O20: =SUM(C20:N20)
B21: Renewal Commission | C21: =C17*Assumptions!D21*Assumptions!D24 | D21: =D17*Assumptions!D21*Assumptions!D24 | E21: =E17*Assumptions!D21*Assumptions!D24 | F21: =F17*Assumptions!D21*Assumptions!D24 | G21: =G17*Assumptions!D21*Assumptions!D24 | H21: =H17*Assumptions!D21*Assumptions!D24 | I21: =I17*Assumptions!D21*Assumptions!D24 | J21: =J17*Assumptions!D21*Assumptions!D24 | K21: =K17*Assumptions!D21*Assumptions!D24 | L21: =L17*Assumptions!D21*Assumptions!D24 | M21: =M17*Assumptions!D21*Assumptions!D24 | N21: =N17*Assumptions!D21*Assumptions!D24 | O21: =SUM(C21:N21)
B22: TOTAL REVENUE | C22: =C20+C21 | D22: =D20+D21 | E22: =E20+E21 | F22: =F20+F21 | G22: =G20+G21 | H22: =H20+H21 | I22: =I20+I21 | J22: =J20+J21 | ... O22: =O20+O21
A24: EXPENSES
B25: Live Transfer Spend | C25: =C8*Assumptions!D6 | D25: =D8*Assumptions!D6 | E25: =E8*Assumptions!D6 | F25: =F8*Assumptions!D6 | G25: =G8*Assumptions!D6 | H25: =H8*Assumptions!D6 | I25: =I8*Assumptions!D6 | J25: =J8*Assumptions!D6 | K25: =K8*Assumptions!D6 | L25: =L8*Assumptions!D6 | M25: =M8*Assumptions!D6 | N25: =N8*Assumptions!D6 | O25: =SUM(C25:N25)
B26: Google Ads Spend | C26: =C9*Assumptions!D7 | D26: =D9*Assumptions!D7 | E26: =E9*Assumptions!D7 | F26: =F9*Assumptions!D7 | G26: =G9*Assumptions!D7 | H26: =H9*Assumptions!D7 | I26: =I9*Assumptions!D7 | J26: =J9*Assumptions!D7 | K26: =K9*Assumptions!D7 | L26: =L9*Assumptions!D7 | M26: =M9*Assumptions!D7 | N26: =N9*Assumptions!D7 | O26: =SUM(C26:N26)
B27: Total Lead Acquisition Cost | C27: =C25+C26 | D27: =D25+D26 | E27: =E25+E26 | F27: =F25+F26 | G27: =G25+G26 | H27: =H25+H26 | I27: =I25+I26 | J27: =J25+J26 | ... O27: =O25+O26
B28: Fixed Costs (from Assumptions) | C28: =Assumptions!C34 | D28: =Assumptions!C34 | E28: =Assumptions!C34 | F28: =Assumptions!C34 | G28: =Assumptions!C34 | H28: =Assumptions!C34 | I28: =Assumptions!C34 | J28: =Assumptions!C34 | K28: =Assumptions!C34 | L28: =Assumptions!C34 | M28: =Assumptions!C34 | N28: =Assumptions!C34 | O28: =SUM(C28:N28)
B29: TOTAL EXPENSES | C29: =C27+C28 | D29: =D27+D28 | E29: =E27+E28 | F29: =F27+F28 | G29: =G27+G28 | H29: =H27+H28 | I29: =I27+I28 | J29: =J27+J28 | ... O29: =O27+O28
A31: BOTTOM LINE
B32: NET PROFIT / (LOSS) | C32: =C22-C29 | D32: =D22-D29 | E32: =E22-E29 | F32: =F22-F29 | G32: =G22-G29 | H32: =H22-H29 | I32: =I22-I29 | J32: =J22-J29 | ... O32: =O22-O29
B33: Profit Margin | C33: =IF(C22=0,0,C32/C22) | D33: =IF(D22=0,0,D32/D22) | E33: =IF(E22=0,0,E32/E22) | F33: =IF(F22=0,0,F32/F22) | G33: =IF(G22=0,0,G32/G22) | H33: =IF(H22=0,0,H32/H22) | I33: =IF(I22=0,0,I32/I22) | J33: =IF(J22=0,0,J32/J22) | ... O33: =IF(O22=0,0,O32/O22)
B34: Cumulative Profit / (Loss) | C34: =C32 | D34: =C34+D32 | E34: =D34+E32 | F34: =E34+F32 | G34: =F34+G32 | H34: =G34+H32 | I34: =H34+I32 | J34: =I34+J32 | K34: =J34+K32 | ... N34: =M34+N32 | O34: =N34
A36: KEY METRICS
B37: Cost Per Funded Deal | C37: =IF(C16=0,0,C29/C16) | D37: =IF(D16=0,0,D29/D16) | E37: =IF(E16=0,0,E29/E16) | F37: =IF(F16=0,0,F29/F16) | G37: =IF(G16=0,0,G29/G16) | H37: =IF(H16=0,0,H29/H16) | I37: =IF(I16=0,0,I29/I16) | J37: =IF(J16=0,0,J29/J16) | ... O37: =IF(O16=0,0,O29/O16)
B38: Revenue Per Funded Deal | C38: =IF(C16+C17=0,0,C22/(C16+C17)) | D38: =IF(D16+D17=0,0,D22/(D16+D17)) | E38: =IF(E16+E17=0,0,E22/(E16+E17)) | F38: =IF(F16+F17=0,0,F22/(F16+F17)) | G38: =IF(G16+G17=0,0,G22/(G16+G17)) | H38: =IF(H16+H17=0,0,H22/(H16+H17)) | I38: =IF(I16+I17=0,0,I22/(I16+I17)) | J38: =IF(J16+J17=0,0,J22/(J16+J17)) | ... O38: =IF(O16+O17=0,0,O22/(O16+O17))
B39: Lead-to-Fund Conversion Rate | C39: =IF(C10=0,0,C16/C10) | D39: =IF(D10=0,0,D16/D10) | E39: =IF(E10=0,0,E16/E10) | F39: =IF(F10=0,0,F16/F10) | G39: =IF(G10=0,0,G16/G10) | H39: =IF(H10=0,0,H16/H10) | I39: =IF(I10=0,0,I16/I10) | J39: =IF(J10=0,0,J16/J10) | ... O39: =IF(O10=0,0,O16/O10)
B40: ROI on Lead Spend | C40: =IF(C27=0,0,(C22-C27)/C27) | D40: =IF(D27=0,0,(D22-D27)/D27) | E40: =IF(E27=0,0,(E22-E27)/E27) | F40: =IF(F27=0,0,(F22-F27)/F27) | G40: =IF(G27=0,0,(G22-G27)/G27) | H40: =IF(H27=0,0,(H22-H27)/H27) | I40: =IF(I27=0,0,(I22-I27)/I27) | J40: =IF(J27=0,0,(J22-J27)/J27) | ... O40: =IF(O27=0,0,(O22-O27)/O27)

Sheet Scenario Comparison
A1: SCENARIO COMPARISON — CONSERVATIVE vs MOST LIKELY vs OPTIMISTIC
A2: Annual projections at full ramp (Month 12 run rate × 12)
C4: Conservative | D4: Most Likely | E4: Optimistic
A6: MONTHLY VOLUME (STEADY STATE)
A7: 1 | B7: Leads / Month | C7: =Assumptions!C8+Assumptions!C9 | D7: =Assumptions!D8+Assumptions!D9 | E7: =Assumptions!E8+Assumptions!E9
A8: 2 | B8: Funded Deals / Month (New) | C8: =(Assumptions!C8+Assumptions!C9)*Assumptions!C14*Assumptions!C15*Assumptions!C16*Assumptions!C17 | D8: =(Assumptions!D8+Assumptions!D9)*Assumptions!D14*Assumptions!D15*Assumptions!D16*Assumptions!D17 | E8: =(Assumptions!E8+Assumptions!E9)*Assumptions!E14*Assumptions!E15*Assumptions!E16*Assumptions!E17
A9: 3 | B9: Renewal Deals / Month | C9: =C8*Assumptions!C23 | D9: =D8*Assumptions!D23 | E9: =E8*Assumptions!E23
A10: 4 | B10: Total Deals / Month | C10: =C8+C9 | D10: =D8+D9 | E10: =E8+E9
A11: MONTHLY REVENUE (STEADY STATE)
A12: 5 | B12: New Deal Commission / Month | C12: =C8*Assumptions!C21*Assumptions!C22 | D12: =D8*Assumptions!D21*Assumptions!D22 | E12: =E8*Assumptions!E21*Assumptions!E22
A13: 6 | B13: Renewal Commission / Month | C13: =C9*Assumptions!C21*Assumptions!C24 | D13: =D9*Assumptions!D21*Assumptions!D24 | E13: =E9*Assumptions!E21*Assumptions!E24
A14: 7 | B14: Total Monthly Revenue | C14: =C12+C13 | D14: =D12+D13 | E14: =E12+E13
A15: MONTHLY COSTS (STEADY STATE)
A16: 8 | B16: Live Transfer Spend | C16: =Assumptions!C8*Assumptions!C6 | D16: =Assumptions!D8*Assumptions!D6 | E16: =Assumptions!E8*Assumptions!E6
A17: 9 | B17: Google Ads Spend | C17: =Assumptions!C9*Assumptions!C7 | D17: =Assumptions!D9*Assumptions!D7 | E17: =Assumptions!E9*Assumptions!E7
A18: 10 | B18: Fixed Costs | C18: =Assumptions!C34 | D18: =Assumptions!C34 | E18: =Assumptions!C34
A19: 11 | B19: Total Monthly Costs | C19: =C16+C17+C18 | D19: =D16+D17+D18 | E19: =E16+E17+E18
A20: MONTHLY PROFIT
A21: 12 | B21: Monthly Net Profit | C21: =C14-C19 | D21: =D14-D19 | E21: =E14-E19
A22: ANNUALIZED (STEADY STATE × 12)
A23: 13 | B23: Annual Revenue | C23: =C14*12 | D23: =D14*12 | E23: =E14*12
A24: 14 | B24: Annual Costs | C24: =C19*12 | D24: =D19*12 | E24: =E19*12
A25: 15 | B25: Annual Net Profit | C25: =C23-C24 | D25: =D23-D24 | E25: =E23-E24
A26: 16 | B26: Annual Profit Margin | C26: =IF(C23=0,0,C25/C23) | D26: =IF(D23=0,0,D25/D23) | E26: =IF(E23=0,0,E25/E23)
A27: 17 | B27: Annual Deals Funded | C27: =C10*12 | D27: =D10*12 | E27: =E10*12
A28: 18 | B28: Total Volume Funded | C28: =C27*Assumptions!C21 | D28: =D27*Assumptions!D21 | E28: =E27*Assumptions!E21
A29: KEY RATIOS
A30: 19 | B30: Cost Per Funded Deal | C30: =IF(C10=0,0,C19/C10) | D30: =IF(D10=0,0,D19/D10) | E30: =IF(E10=0,0,E19/E10)
A31: 20 | B31: Revenue Per Funded Deal | C31: =IF(C10=0,0,C14/C10) | D31: =IF(D10=0,0,D14/D10) | E31: =IF(E10=0,0,E14/E10)
A32: 21 | B32: Lead-to-Fund Conversion | C32: =Assumptions!C14*Assumptions!C15*Assumptions!C16*Assumptions!C17 | D32: =Assumptions!D14*Assumptions!D15*Assumptions!D16*Assumptions!D17 | E32: =Assumptions!E14*Assumptions!E15*Assumptions!E16*Assumptions!E17
A33: 22 | B33: ROI on Lead Spend | C33: =IF(C16+C17=0,0,(C14-(C16+C17))/(C16+C17)) | D33: =IF(D16+D17=0,0,(D14-(D16+D17))/(D16+D17)) | E33: =IF(E16+E17=0,0,(E14-(E16+E17))/(E16+E17))
A34: 23 | B34: Months to Break Even (approx) | C34: =IF(C21<=0,"N/A",C19/C21) | D34: =IF(D21<=0,"N/A",D19/D21) | E34: =IF(E21<=0,"N/A",E19/E21)

Sheet Market Allocation
A1: MARKET ALLOCATION — BUDGET & LEAD DISTRIBUTION BY CITY
A2: Based on Most Likely scenario — adjust allocation % to shift focus between markets
B4: Market | C4: Allocation % | D4: Leads/Month | E4: Monthly Lead Spend | F4: Est. Deals Funded/Mo | G4: Monthly Revenue | H4: Monthly Profit | I4: Priority Rank
A5: 1 | B5: Indianapolis, IN | C5: 0.2 | D5: =C5*Assumptions!D10 | E5: =D5*((Assumptions!D6*Assumptions!D8+Assumptions!D7*Assumptions!D9)/Assumptions!D10) | F5: =D5*Assumptions!D14*Assumptions!D15*Assumptions!D16*Assumptions!D17 | G5: =F5*Assumptions!D21*Assumptions!D22 | H5: =G5-E5-(C5*Assumptions!C34) | I5: 1
A6: 2 | B6: Phoenix / Scottsdale, AZ | C6: 0.2 | D6: =C6*Assumptions!D10 | E6: =D6*((Assumptions!D6*Assumptions!D8+Assumptions!D7*Assumptions!D9)/Assumptions!D10) | F6: =D6*Assumptions!D14*Assumptions!D15*Assumptions!D16*Assumptions!D17 | G6: =F6*Assumptions!D21*Assumptions!D22 | H6: =G6-E6-(C6*Assumptions!C34) | I6: 2
A7: 3 | B7: Columbus / Cincinnati, OH | C7: 0.2 | D7: =C7*Assumptions!D10 | E7: =D7*((Assumptions!D6*Assumptions!D8+Assumptions!D7*Assumptions!D9)/Assumptions!D10) | F7: =D7*Assumptions!D14*Assumptions!D15*Assumptions!D16*Assumptions!D17 | G7: =F7*Assumptions!D21*Assumptions!D22 | H7: =G7-E7-(C7*Assumptions!C34) | I7: 3
A8: 4 | B8: Washington DC / NoVA | C8: 0.15 | D8: =C8*Assumptions!D10 | E8: =D8*((Assumptions!D6*Assumptions!D8+Assumptions!D7*Assumptions!D9)/Assumptions!D10) | F8: =D8*Assumptions!D14*Assumptions!D15*Assumptions!D16*Assumptions!D17 | G8: =F8*Assumptions!D21*Assumptions!D22 | H8: =G8-E8-(C8*Assumptions!C34) | I8: 4
A9: 5 | B9: Sacramento, CA | C9: 0.1 | D9: =C9*Assumptions!D10 | E9: =D9*((Assumptions!D6*Assumptions!D8+Assumptions!D7*Assumptions!D9)/Assumptions!D10) | F9: =D9*Assumptions!D14*Assumptions!D15*Assumptions!D16*Assumptions!D17 | G9: =F9*Assumptions!D21*Assumptions!D22 | H9: =G9-E9-(C9*Assumptions!C34) | I9: 5
A10: 6 | B10: South Florida (Home) | C10: 0.15 | D10: =C10*Assumptions!D10 | E10: =D10*((Assumptions!D6*Assumptions!D8+Assumptions!D7*Assumptions!D9)/Assumptions!D10) | F10: =D10*Assumptions!D14*Assumptions!D15*Assumptions!D16*Assumptions!D17 | G10: =F10*Assumptions!D21*Assumptions!D22 | H10: =G10-E10-(C10*Assumptions!C34) | I10: 6
B11: TOTALS | C11: =SUM(C5:C10) | D11: =SUM(D5:D10) | E11: =SUM(E5:E10) | F11: =SUM(F5:F10) | G11: =SUM(G5:G10) | H11: =SUM(H5:H10)
A13: MARKET NOTES
B14: Indianapolis, IN | C14: Hot — #5 best state, massive construction
B15: Phoenix / Scottsdale, AZ | C15: Explosive growth, exceeding national avg
B16: Columbus / Cincinnati, OH | C16: #4 best state, hospital & airport projects
B17: Washington DC / NoVA | C17: Data center boom, $178M YOY growth
B18: Sacramento, CA | C18: State capital, gov contractor demand
B19: South Florida (Home) | C19: Home base — lower volume but local presence

Sheet Break-Even
A1: BREAK-EVEN ANALYSIS — HOW MANY DEALS TO COVER COSTS?
A2: Minimum deals needed per month to break even under each scenario
C4: Conservative | D4: Most Likely | E4: Optimistic
A5: 1 | B5: Revenue Per New Deal | C5: =Assumptions!C21*Assumptions!C22 | D5: =Assumptions!D21*Assumptions!D22 | E5: =Assumptions!E21*Assumptions!E22
A6: 2 | B6: Total Monthly Fixed Costs | C6: =Assumptions!C34 | D6: =Assumptions!C34 | E6: =Assumptions!C34
A7: 3 | B7: Avg Cost Per Lead (blended) | C7: =(Assumptions!C6*Assumptions!C8+Assumptions!C7*Assumptions!C9)/(Assumptions!C8+Assumptions!C9) | D7: =(Assumptions!D6*Assumptions!D8+Assumptions!D7*Assumptions!D9)/(Assumptions!D8+Assumptions!D9) | E7: =(Assumptions!E6*Assumptions!E8+Assumptions!E7*Assumptions!E9)/(Assumptions!E8+Assumptions!E9)
A8: 4 | B8: Lead-to-Fund Conversion Rate | C8: =Assumptions!C14*Assumptions!C15*Assumptions!C16*Assumptions!C17 | D8: =Assumptions!D14*Assumptions!D15*Assumptions!D16*Assumptions!D17 | E8: =Assumptions!E14*Assumptions!E15*Assumptions!E16*Assumptions!E17
A9: 5 | B9: Cost in Leads Per Funded Deal | C9: =IF(C8=0,0,C7/C8) | D9: =IF(D8=0,0,D7/D8) | E9: =IF(E8=0,0,E7/E8)
A10: 6 | B10: Net Profit Per Funded Deal | C10: =C5-C9 | D10: =D5-D9 | E10: =E5-E9
A11: 7 | B11: Deals to Cover Fixed Costs | C11: =IF(C10=0,"N/A",CEILING(C6/C10,1)) | D11: =IF(D10=0,"N/A",CEILING(D6/D10,1)) | E11: =IF(E10=0,"N/A",CEILING(E6/E10,1))
A12: 8 | B12: Deals to Cover ALL Costs | C12: =IF(C10=0,"N/A",CEILING((C6+(Assumptions!C8+Assumptions!C9)*C7)/C5,1)) | D12: =IF(D10=0,"N/A",CEILING((D6+(Assumptions!D8+Assumptions!D9)*D7)/D5,1)) | E12: =IF(E10=0,"N/A",CEILING((E6+(Assumptions!E8+Assumptions!E9)*E7)/E5,1))
B15: INTERPRETATION: 'Deals to Cover Fixed Costs' shows how many funded deals per month you need just to keep the lights on (before lead costs). 'Deals to Cover ALL Costs' shows total deals needed to break even including your lead acquisition spend. Anything above that number is pure profit. Blue values on the Assumptions tab are adjustable — change them to model your specific situation.

Sheet Scaling P&L
A1: 24-MONTH SCALING P&L WITH STAFFING PHASES
A2: Most Likely scenario — Shows exactly when to hire, what to pay, and how profit scales
C4: M1 | D4: M2 | E4: M3 | F4: M4 | G4: M5 | H4: M6 | I4: M7 | J4: M8 | K4: M9 | L4: M10 | M4: M11 | N4: M12 | O4: M13 | P4: M14 | Q4: M15 | R4: M16 | S4: M17 | T4: M18 | U4: M19 | V4: M20 | W4: M21 | X4: M22 | Y4: M23 | Z4: M24 | AA4: TOTAL
B5: PHASE | C5: PHASE 1: Solo | F5: PHASE 2: +Closer 1 | I5: PHASE 3: +VA +Closer 2 | L5: PHASE 4: +Sales Mgr | O5: PHASE 4 cont. | U5: PHASE 5: Mature
A7: STAFFING
B8: Closers (besides you) | C8: 0 | D8: 0 | E8: 0 | F8: 1 | G8: 1 | H8: 1 | I8: 2 | J8: 2 | K8: 2 | L8: 3 | M8: 3 | N8: 3 | O8: 3 | P8: 3 | Q8: 3 | R8: 4 | S8: 4 | T8: 4 | U8: 4 | V8: 4 | W8: 5 | X8: 5 | Y8: 5 | Z8: 5
B9: VAs / Deal Coordinators | C9: 0 | D9: 0 | E9: 0 | F9: 0 | G9: 0 | H9: 0 | I9: 1 | J9: 1 | K9: 1 | L9: 1 | M9: 1 | N9: 1 | O9: 1 | P9: 1 | Q9: 1 | R9: 2 | S9: 2 | T9: 2 | U9: 2 | V9: 2 | W9: 2 | X9: 2 | Y9: 2 | Z9: 2
B10: Sales Manager | C10: 0 | D10: 0 | E10: 0 | F10: 0 | G10: 0 | H10: 0 | I10: 0 | J10: 0 | K10: 0 | L10: 1 | M10: 1 | N10: 1 | O10: 1 | P10: 1 | Q10: 1 | R10: 1 | S10: 1 | T10: 1 | U10: 1 | V10: 1 | W10: 1 | X10: 1 | Y10: 1 | Z10: 1
B11: Marketing Person | C11: 0 | D11: 0 | E11: 0 | F11: 0 | G11: 0 | H11: 0 | I11: 0 | J11: 0 | K11: 0 | L11: 0 | M11: 0 | N11: 0 | O11: 0 | P11: 0 | Q11: 0 | R11: 0 | S11: 0 | T11: 0 | U11: 1 | V11: 1 | W11: 1 | X11: 1 | Y11: 1 | Z11: 1
B12: Renewals Specialist | C12: 0 | D12: 0 | E12: 0 | F12: 0 | G12: 0 | H12: 0 | I12: 0 | J12: 0 | K12: 0 | L12: 0 | M12: 0 | N12: 1 | O12: 1 | P12: 1 | Q12: 1 | R12: 1 | S12: 1 | T12: 1 | U12: 1 | V12: 1 | W12: 1 | X12: 1 | Y12: 1 | Z12: 1
B13: Total Team Size | C13: =SUM(C8:C12) | D13: =SUM(D8:D12) | E13: =SUM(E8:E12) | F13: =SUM(F8:F12) | G13: =SUM(G8:G12) | H13: =SUM(H8:H12) | I13: =SUM(I8:I12) | J13: =SUM(J8:J12) | ... Z13: =SUM(Z8:Z12)
A15: LEAD VOLUME
B16: Leads / Month | C16: 35 | D16: 50 | E16: 70 | F16: 100 | G16: 100 | H16: 100 | I16: 140 | J16: 140 | K16: 150 | L16: 180 | M16: 200 | N16: 200 | O16: 200 | P16: 200 | Q16: 200 | R16: 230 | S16: 250 | T16: 250 | U16: 250 | V16: 250 | W16: 280 | X16: 280 | Y16: 300 | Z16: 300 | AA16: =SUM(C16:Z16)
A18: DEALS FUNDED
B19: Conversion Rate (lead to fund) | C19: 0.08 | D19: 0.09 | E19: 0.1 | F19: 0.1 | G19: 0.11 | H19: 0.11 | I19: 0.11 | J19: 0.12 | K19: 0.12 | L19: 0.12 | M19: 0.12 | N19: 0.12 | O19: 0.12 | P19: 0.12 | Q19: 0.12 | R19: 0.13 | S19: 0.13 | T19: 0.13 | U19: 0.13 | V19: 0.13 | W19: 0.14 | X19: 0.14 | Y19: 0.14 | Z19: 0.14
B20: New Deals Funded | C20: =C16*C19 | D20: =D16*D19 | E20: =E16*E19 | F20: =F16*F19 | G20: =G16*G19 | H20: =H16*H19 | I20: =I16*I19 | J20: =J16*J19 | ... Z20: =Z16*Z19 | AA20: =SUM(C20:Z20)
B21: Renewal Deals | C21: 0 | D21: 0 | E21: 0 | F21: 0 | G21: 0 | H21: 0 | I21: =C20*0.45 | J21: =D20*0.45 | K21: =E20*0.45 | L21: =F20*0.45 | M21: =G20*0.45 | N21: =H20*0.45 | O21: =I20*0.45 | P21: =J20*0.45 | ... Z21: =T20*0.45 | AA21: =SUM(C21:Z21)
B22: Total Deals | C22: =C20+C21 | D22: =D20+D21 | E22: =E20+E21 | F22: =F20+F21 | G22: =G20+G21 | H22: =H20+H21 | I22: =I20+I21 | J22: =J20+J21 | ... Z22: =Z20+Z21 | AA22: =SUM(C22:Z22)
A24: REVENUE
B25: Avg Deal Size | C25: 50000 | D25: 50000 | E25: 50000 | F25: 50000 | G25: 50000 | H25: 50000 | I25: 50000 | J25: 50000 | K25: 50000 | L25: 50000 | M25: 50000 | N25: 50000 | O25: 50000 | P25: 50000 | Q25: 50000 | R25: 50000 | S25: 50000 | T25: 50000 | U25: 50000 | V25: 50000 | W25: 50000 | X25: 50000 | Y25: 50000 | Z25: 50000
B26: Commission Points | C26: 0.08 | D26: 0.08 | E26: 0.08 | F26: 0.08 | G26: 0.08 | H26: 0.08 | I26: 0.08 | J26: 0.08 | K26: 0.08 | L26: 0.08 | M26: 0.08 | N26: 0.08 | O26: 0.08 | P26: 0.08 | Q26: 0.08 | R26: 0.08 | S26: 0.08 | T26: 0.08 | U26: 0.08 | V26: 0.08 | W26: 0.08 | X26: 0.08 | Y26: 0.08 | Z26: 0.08
B27: GROSS COMMISSION REVENUE | C27: =C22*C25*C26 | D27: =D22*D25*D26 | E27: =E22*E25*E26 | F27: =F22*F25*F26 | G27: =G22*G25*G26 | H27: =H22*H25*H26 | I27: =I22*I25*I26 | J27: =J22*J25*J26 | ... Z27: =Z22*Z25*Z26 | AA27: =SUM(C27:Z27)
A29: EXPENSES
B30: Lead Acquisition (avg $70/lead) | C30: =C16*70 | D30: =D16*70 | E30: =E16*70 | F30: =F16*70 | G30: =G16*70 | H30: =H16*70 | I30: =I16*70 | J30: =J16*70 | ... Z30: =Z16*70 | AA30: =SUM(C30:Z30)
B31: Closer Commissions (50% split) | C31: =IF(C8>0,(C8/(C8+1))*C27*0.50,0) | D31: =IF(D8>0,(D8/(D8+1))*D27*0.50,0) | E31: =IF(E8>0,(E8/(E8+1))*E27*0.50,0) | F31: =IF(F8>0,(F8/(F8+1))*F27*0.50,0) | G31: =IF(G8>0,(G8/(G8+1))*G27*0.50,0) | H31: =IF(H8>0,(H8/(H8+1))*H27*0.50,0) | I31: =IF(I8>0,(I8/(I8+1))*I27*0.50,0) | J31: =IF(J8>0,(J8/(J8+1))*J27*0.50,0) | ... Z31: =IF(Z8>0,(Z8/(Z8+1))*Z27*0.50,0) | AA31: =SUM(C31:Z31)
B32: Sales Manager ($3.5K + 7% override) | C32: =C10*(3500+C27*0.07) | D32: =D10*(3500+D27*0.07) | E32: =E10*(3500+E27*0.07) | F32: =F10*(3500+F27*0.07) | G32: =G10*(3500+G27*0.07) | H32: =H10*(3500+H27*0.07) | I32: =I10*(3500+I27*0.07) | J32: =J10*(3500+J27*0.07) | ... Z32: =Z10*(3500+Z27*0.07) | AA32: =SUM(C32:Z32)
B33: VAs ($1,200/mo each) | C33: =C9*1200 | D33: =D9*1200 | E33: =E9*1200 | F33: =F9*1200 | G33: =G9*1200 | H33: =H9*1200 | I33: =I9*1200 | J33: =J9*1200 | ... Z33: =Z9*1200 | AA33: =SUM(C33:Z33)
B34: Renewals Specialist (35% split) | C34: =C12*C21*C25*0.06*0.35 | D34: =D12*D21*D25*0.06*0.35 | E34: =E12*E21*E25*0.06*0.35 | F34: =F12*F21*F25*0.06*0.35 | G34: =G12*G21*G25*0.06*0.35 | H34: =H12*H21*H25*0.06*0.35 | I34: =I12*I21*I25*0.06*0.35 | J34: =J12*J21*J25*0.06*0.35 | ... Z34: =Z12*Z21*Z25*0.06*0.35 | AA34: =SUM(C34:Z34)
B35: Marketing Person ($5K/mo) | C35: =C11*5000 | D35: =D11*5000 | E35: =E11*5000 | F35: =F11*5000 | G35: =G11*5000 | H35: =H11*5000 | I35: =I11*5000 | J35: =J11*5000 | ... Z35: =Z11*5000 | AA35: =SUM(C35:Z35)
B36: Fixed Costs (tech + overhead) | C36: =1247+C8*150 | D36: =1247+D8*150 | E36: =1247+E8*150 | F36: =1247+F8*150 | G36: =1247+G8*150 | H36: =1247+H8*150 | I36: =1247+I8*150 | J36: =1247+J8*150 | ... Z36: =1247+Z8*150 | AA36: =SUM(C36:Z36)
B37: Closer Draws (ramp-up) | C37: 0 | D37: 0 | E37: 0 | F37: 2500 | G37: 2500 | H37: 2500 | I37: 2500 | J37: 2500 | K37: 2500 | L37: 2500 | M37: 2500 | N37: 2500 | O37: 0 | P37: 0 | Q37: 0 | R37: 2500 | S37: 2500 | T37: 2500 | U37: 0 | V37: 0 | W37: 2500 | X37: 2500 | Y37: 2500 | Z37: 2500 | AA37: =SUM(C37:Z37)
B38: TOTAL EXPENSES | C38: =SUM(C30:C37) | D38: =SUM(D30:D37) | E38: =SUM(E30:E37) | F38: =SUM(F30:F37) | G38: =SUM(G30:G37) | H38: =SUM(H30:H37) | I38: =SUM(I30:I37) | J38: =SUM(J30:J37) | ... Z38: =SUM(Z30:Z37) | AA38: =SUM(C38:Z38)
A40: YOUR TAKE-HOME
B41: YOUR MONTHLY NET PROFIT | C41: =C27-C38 | D41: =D27-D38 | E41: =E27-E38 | F41: =F27-F38 | G41: =G27-G38 | H41: =H27-H38 | I41: =I27-I38 | J41: =J27-J38 | ... Z41: =Z27-Z38 | AA41: =SUM(C41:Z41)
B42: Profit Margin | C42: =IF(C27=0,0,C41/C27) | D42: =IF(D27=0,0,D41/D27) | E42: =IF(E27=0,0,E41/E27) | F42: =IF(F27=0,0,F41/F27) | G42: =IF(G27=0,0,G41/G27) | H42: =IF(H27=0,0,H41/H27) | I42: =IF(I27=0,0,I41/I27) | J42: =IF(J27=0,0,J41/J27) | ... AA42: =IF(AA27=0,0,AA41/AA27)
B43: Cumulative Net Profit | C43: =C41 | D43: =C43+D41 | E43: =D43+E41 | F43: =E43+F41 | G43: =F43+G41 | H43: =G43+H41 | I43: =H43+I41 | J43: =I43+J41 | K43: =J43+K41 | ... Z43: =Y43+Z41 | AA43: =Z43
A45: KEY METRICS
B46: Revenue Per Deal | C46: =IF(C22=0,0,C27/C22) | D46: =IF(D22=0,0,D27/D22) | E46: =IF(E22=0,0,E27/E22) | F46: =IF(F22=0,0,F27/F22) | G46: =IF(G22=0,0,G27/G22) | H46: =IF(H22=0,0,H27/H22) | I46: =IF(I22=0,0,I27/I22) | J46: =IF(J22=0,0,J27/J22) | ... Z46: =IF(Z22=0,0,Z27/Z22)
B47: Total Cost Per Deal | C47: =IF(C22=0,0,C38/C22) | D47: =IF(D22=0,0,D38/D22) | E47: =IF(E22=0,0,E38/E22) | F47: =IF(F22=0,0,F38/F22) | G47: =IF(G22=0,0,G38/G22) | H47: =IF(H22=0,0,H38/H22) | I47: =IF(I22=0,0,I38/I22) | J47: =IF(J22=0,0,J38/J22) | ... Z47: =IF(Z22=0,0,Z38/Z22)
B48: Your Profit Per Deal | C48: =IF(C22=0,0,C41/C22) | D48: =IF(D22=0,0,D41/D22) | E48: =IF(E22=0,0,E41/E22) | F48: =IF(F22=0,0,F41/F22) | G48: =IF(G22=0,0,G41/G22) | H48: =IF(H22=0,0,H41/H22) | I48: =IF(I22=0,0,I41/I22) | J48: =IF(J22=0,0,J41/J22) | ... Z48: =IF(Z22=0,0,Z41/Z22)
...

Sheet Compensation Guide
A1: MCA BROKERAGE COMPENSATION GUIDE
A2: Industry-standard pay structures for each role in your scaling plan
B4: Role | C4: Type | D4: Base / Fixed | E4: Variable / Commission | F4: Expected Monthly Earnings | G4: Annual OTE | H4: Key Terms & Notes
B5: MCA Closer (Company Leads) | C5: 1099 IC | D5: $0 (or $2.5K draw x 90 days) | E5: 40-50% of company commission per funded deal | F5: $8,000 - $20,000 | G5: $96K - $240K | H5: Commission-only after draw period. 50/50 split on company leads is industry standard. Draw is recoverable advance, deducted from future earnings.
B6: MCA Closer (Self-Gen) | C6: 1099 IC | D6: $0 | E6: 60-70% of company commission per self-sourced deal | F6: $5,000 - $15,000 (addtl) | G6: $60K - $180K (addtl) | H6: Higher split because rep sourced the lead at their own cost. Rep brings own book of business. Can combine with company-lead role.
B7: VA / Deal Coordinator | C7: Offshore Contractor | D7: $800 - $1,500/month flat | E7: None (or small per-deal bonus of $25-$50) | F7: $800 - $1,800 | G7: $9.6K - $21.6K | H7: Philippines or Latin America. Handles doc collection, CRM updates, funder submissions. Highest ROI hire — multiplies closer productivity 2-3x.
B8: Sales Manager / Floor Lead | C8: W-2 or 1099 | D8: $3,000 - $4,000/month base | E8: 5-10% override on ALL team deals funded | F8: $8,000 - $15,000 | G8: $96K - $180K | H8: Manages closers, morning huddles, call quality, escalations. Override aligns their income with team performance. Hire at 4+ closers.
B9: Renewals Specialist | C9: 1099 IC | D9: $0 | E9: 30-40% of renewal commission (6 pts) | F9: $3,000 - $8,000 | G9: $36K - $96K | H9: Works existing funded book for repeat business. Lower split because leads are warm/free. 45% of merchants seek more capital within 6 months.
B10: Marketing / Lead Gen | C10: W-2 or Agency | D10: $4,000 - $6,000/month | E10: Performance bonus tied to cost-per-lead reduction | F10: $4,500 - $7,000 | G10: $54K - $84K | H10: Manages Google Ads, SEO, content, landing pages. Goal: reduce avg CPL from $70 to $40-50 over 6 months. Hire in Year 2 to internalize lead gen.
B11: Sub-ISO Partner | C11: 1099 IC | D11: $0 | E11: You keep 1-2 point override on their funded volume | F11: Varies (pure margin to you) | G11: Varies | H11: Other brokers submit deals through your funder network. You earn override with zero lead cost. Use LendSaaS whitelabel portal.
A14: COMMISSION MATH EXAMPLES
B15: Scenario | C15: Deal Size | D15: Points from Funder | E15: Gross Commission | F15: Closer Split % | G15: Closer Earns | H15: You Keep
B16: Company lead → Closer funds $50K deal | C16: $50,000 | D16: 8 pts | E16: $4,000 | F16: 50% | G16: $2,000 | H16: $2,000
B17: Company lead → Closer funds $100K deal | C17: $100,000 | D17: 8 pts | E17: $8,000 | F17: 50% | G17: $4,000 | H17: $4,000
B18: Self-gen lead → Closer funds $50K deal | C18: $50,000 | D18: 8 pts | E18: $4,000 | F18: 70% | G18: $2,800 | H18: $1,200
B19: Renewal → Specialist funds $50K deal | C19: $50,000 | D19: 6 pts | E19: $3,000 | F19: 35% | G19: $1,050 | H19: $1,950
B20: Sub-ISO partner funds $75K deal | C20: $75,000 | D20: 8 pts | E20: $6,000 | F20: N/A | G20: Sub keeps 6 pts | H20: $1,500 (2 pt override)
B21: YOU close a $50K deal directly | C21: $50,000 | D21: 8 pts | E21: $4,000 | F21: 0% (you) | G21: $0 | H21: $4,000 (100%)

Sheet Hiring Roadmap
A1: HIRING ROADMAP & DECISION TRIGGERS
A2: When to hire each role — based on metrics, not calendar dates
B4: Phase | C4: Role to Hire | D4: Trigger / When to Hire | E4: What They Do | F4: Compensation | G4: Success Metrics
B5: PHASE 1 (Months 1-3) | C5: YOU (Solo) | D5: Day 1. You ARE the business. Prove unit economics before hiring anyone. | E5: Close all deals personally. Build funder relationships. Test markets. Learn your real conversion rates. | F5: N/A — you keep 100% of commissions | G5: 5+ deals/month funded. Know your cost-per-funded-deal. Positive monthly cash flow.
B6: PHASE 2 (Month 4+) | C6: MCA Closer #1 | D6: You are consistently funding 5+ deals/month AND turning away or losing leads because you can’t get to them fast enough. | E6: Takes live transfers, works leads, closes deals. Full sales cycle from qualification to funding. | F6: 1099: 50% split on company leads, 70% on self-gen. Optional $2,500/mo draw for 90 days. | G6: Closer funds 4+ deals/month within 60 days. Revenue from their deals exceeds their commission + lead cost.
B7: PHASE 3 (Month 6+) | C7: VA / Deal Coordinator | D7: You and Closer #1 are spending 30%+ of time on admin: chasing docs, submitting to funders, updating CRM. This is killing your close time. | E7: Doc collection from merchants. Packages and submits deals to funders. Updates pipeline/CRM. Manages follow-up sequences. | F7: $1,200/month flat (Philippines or LatAm). Optional $25-$50 per-deal bonus. | G7: Submission turnaround drops from 48hrs to same-day. Closer talk time increases 40%+. Zero missed follow-ups.
B8: PHASE 3 (Month 6+) | C8: MCA Closer #2 | D8: Lead flow exceeds 100/month AND Closer #1 is at capacity (50+ leads). You have budget from Closer #1’s production. | E8: Same as Closer #1. Works their own pipeline. Covers different shifts or markets. | F8: Same as Closer #1: 50% split company leads, $2,500 draw for 90 days. | G8: Combined team funds 12+ deals/month. Each closer maintains 10%+ conversion rate.
B9: PHASE 4 (Month 9-12) | C9: Sales Manager | D9: You have 3+ closers AND you are spending more time managing people than growing the business. You need to step off the sales floor. | E9: Manages closers. Morning huddles. Call monitoring and coaching. Handles escalations. Onboards new closers. | F9: $3,500/mo base + 7% override on ALL team deals funded. | G9: Team conversion rate improves. Closer ramp time shortens. You reclaim 80%+ of your time for business development.
B10: PHASE 4 (Month 10+) | C10: Renewals Specialist | D10: Your funded book exceeds 50 merchants AND you have 6+ months of deal history. Renewal opportunities are going unworked. | E10: Contacts previously funded merchants at 4-5 month mark. Offers additional capital. Manages renewal pipeline separately. | F10: 1099: 35% split on renewal commissions (6 points). Commission-only. | G10: 40%+ of eligible merchants take renewal. Avg 5-10 renewal deals/month. Revenue at near-zero lead cost.
B11: PHASE 5 (Year 2) | C11: Marketing / Lead Gen | D11: Your cost-per-lead from live transfers and Google Ads is stable but you want to reduce it. You need SEO, content, and optimized ad spend. | E11: Manages all Google Ads campaigns. Builds city-specific SEO landing pages. Creates content. Optimizes cost-per-lead. | F11: $5,000/month salary or agency retainer. Performance bonus for CPL reduction. | G11: CPL drops from $70 to $40-50 within 6 months. Organic leads begin contributing 15-20% of pipeline.
B12: PHASE 5 (Year 2+) | C12: Sub-ISO Partners | D12: You have strong funder relationships and excess capacity. Other small brokers ask to submit through you. | E12: Independent brokers submit their deals through your funder network. You handle funder relationship. They handle merchant. | F12: You keep 1-2 point override on every funded deal. Zero lead cost, zero payroll. | G12: Each active sub-ISO adds 3-5 deals/month. Pure margin. Scale to 5-10 sub-ISOs for $10K-$30K+/month passive override income.
B14: ⚠️ GOLDEN RULE: Never hire ahead of your lead supply. Each closer needs 40-50 leads/month to stay productive. If you hire before you have the leads, they’ll starve and quit. Scaling sequence: Prove leads convert → Hire closer → Add VA → Increase lead flow → Hire another closer → Repeat.
A16: RED FLAGS: DON’T HIRE YET IF...
B17: ❌ You haven’t personally funded at least 15 deals (you won’t know what good looks like to train others)
B18: ❌ Your lead-to-fund conversion is below 8% (fix your process before scaling it)
B19: ❌ You don’t have at least 3 funder relationships established (closers need options to present merchants)
B20: ❌ Monthly revenue doesn’t cover the new hire’s expected cost within 60 days
B21: ❌ You’re hiring to fix a conversion problem (hire to handle VOLUME, not to fix QUALITY)

Sheet Sub-ISO Economics
A1: SUB-ISO PROGRAM ECONOMICS
A2: Revenue projections from Sub-ISO override commissions + platform fees
A4: PER-DEAL ECONOMICS (Your Override on Sub-ISO Deals)
B5: Average Deal Size | C5: $50,000 | D5: Editable assumption
B6: Funder Pays Total Commission | C6: 8 points | D6: 8% of deal = $4,000
B7: MFunding Override | C7: 2 points | D7: $1,000 retained by MFunding
B8: Sub-ISO Keeps | C8: 6 points | D8: $3,000 paid to Sub-ISO
B10: Your Lead Cost for This Deal | C10: $0 | D10: Sub-ISO sourced the merchant
B11: Your Closer Cost for This Deal | C11: $0 | D11: Sub-ISO did the selling
B12: Your VA Cost (submission processing) | C12: ~$15 | D12: Minimal time per deal
B14: YOUR NET PROFIT PER SUB-ISO DEAL | C14: $985 | D14: Nearly pure margin
A17: SUB-ISO PROGRAM SCALING PROJECTIONS
B18: Metric | C18: Conservative | D18: Moderate | E18: Aggressive | F18: Notes
B19: Active Sub-ISOs | C19: 3 | D19: 7 | E19: 15 | F19: Recruited over 6-12 months
B20: Avg Deals Per Sub-ISO / Month | C20: 2 | D20: 4 | E20: 5 | F20: Varies by Sub-ISO experience
B21: Total Sub-ISO Deals / Month | C21: 6 | D21: 28 | E21: 75 | F21: =Sub-ISOs × deals each
B22: Override Per Deal (2 pts on $50K) | C22: $1,000 | D22: $1,000 | E22: $1,000 | F22: Fixed per deal
B23: Monthly Override Revenue | C23: $6,000 | D23: $28,000 | E23: $75,000 | F23: =Deals × $1,000
B25: Platform Fee Per Sub-ISO | C25: $149 | D25: $149 | E25: $149 | F25: Monthly GHL access fee
B26: Monthly Platform Fee Revenue | C26: $447 | D26: $1,043 | E26: $2,235 | F26: =Sub-ISOs × $149
B27: Usage Markup Revenue (est.) | C27: $150 | D27: $500 | E27: $1,500 | F27: SMS/phone/email margin
B29: TOTAL MONTHLY SUB-ISO REVENUE | C29: $6,597 | D29: $29,543 | E29: $78,735 | F29: Override + fees + markup
B30: Monthly Cost (VA time, GHL incr.) | C30: ($300) | D30: ($700) | E30: ($1,500) | F30: Minimal incremental cost
B31: MONTHLY SUB-ISO NET PROFIT | C31: $6,297 | D31: $28,843 | E31: $77,235 | F31: Nearly all margin
B33: ANNUAL SUB-ISO NET PROFIT | C33: $75,564 | D33: $346,116 | E33: $926,820 | F33: On top of direct brokerage profits
A36: COMBINED BUSINESS (Year 2 Steady State — Moderate Scenario)
B37: Revenue Stream | C37: Monthly | D37: Annual
B38: Direct Brokerage Net Profit (from Scaling P&L) | C38: $45,000/month | D38: $540,000/year
B39: Sub-ISO Override + Fees Net Profit | C39: $28,843/month | D39: $346,116/year
B41: TOTAL COMBINED NET PROFIT | C41: $73,843/month | D41: $886,116/year
B43: KEY INSIGHT: Sub-ISO revenue is nearly pure margin because you pay $0 for leads and $0 for closers on those deals. The Sub-ISO program can eventually generate MORE profit than your direct brokerage operations, with LESS operational effort. This is how you transition from brokerage operator to platform owner.
A46: GHL PLATFORM FEE REVENUE (Additional Recurring Income)
B47: GHL SaaS Pro Cost (your cost) | C47: $497/month | D47: Fixed regardless of sub-ISOs
B48: Sub-ISO Platform Fee (you charge) | C48: $99–$199/month each | D48: Recurring revenue per partner
B49: Break-even on GHL cost | C49: 3–5 Sub-ISOs at $99–$149 | D49: GHL pays for itself
B50: 10 Sub-ISOs at $149/month | C50: $1,490/month revenue | D50: $993/month profit after GHL cost
B51: 20 Sub-ISOs at $149/month | C51: $2,980/month revenue | D51: $2,483/month profit after GHL cost
B52: SMS/Phone Markup (10 Sub-ISOs) | C52: $500–$1,500/month | D52: Depends on usage volume
